Workbook
Name NativeTimeline_Date: #N/A
Name Slicer_Accident_Location_Details: #N/A
Name Slicer_Accident_Severity: #N/A
Name Slicer_Driver_Gender: #N/A
Name Slicer_Driver_License_Status: #N/A
Name Slicer_Month: #N/A
Name Slicer_Road_Type: #N/A
Name Slicer_Speed_Band: #N/A
Name Slicer_State_Initial: #N/A
Name Slicer_State_Name: #N/A
Name Slicer_Vehicle_Type_Involved: #N/A
Name Slicer_Weather_Conditions: #N/A
Name Slicer_Year: #N/A

Sheet Sheet9
A3: Row Labels | B3: Count of Accident_ID
A4: Goa | B4: 109
A5: Sikkim | B5: 108
A6: Delhi | B6: 108
A7: Uttarakhand | B7: 106
A8: Jammu and Kashmir | B8: 105
A9: Grand Total | B9: 536

Sheet Lookup
A1: State Name | B1: State Code
A2: Andhra Pradesh | B2: AP
A3: Arunachal Pradesh | B3: AR
A4: Assam | B4: AS
A5: Bihar | B5: BR
A6: Chandigarh | B6: CH
A7: Chhattisgarh | B7: CG
A8: Delhi | B8: DL
A9: Goa | B9: GA
A10: Gujarat | B10: GJ
A11: Haryana | B11: HR
A12: Himachal Pradesh | B12: HP
... A33: West Bengal | B33: WB

Sheet Cleaned_Data
A1: Accident_ID | B1: Accident_Flag | C1: State Name | D1: State Initial | E1: City Name | F1: Year | G1: Month | H1: Month_Number | I1: Date | J1: Day of Week | K1: Time of Day | L1: Accident Severity | M1: Number of Vehicles Involved | N1: Vehicle Type Involved | O1: Number of Casualties | P1: Number of Fatalities | Q1: Weather Conditions | R1: Road Type | S1: Road Condition | T1: Lighting Conditions | U1: Traffic Control Presence | V1: Speed Limit (km/h) | W1: Driver Age | X1: Age_young_old | Y1: Driver Gender | Z1: Driver License Status | AA1: Alcohol Involvement | AB1: Accident Location Details | AC1: hour | AD1: Time_Bin | AE1: Phase | AF1: Weekend | AG1: Is_Fatal | AH1: Fatality_Rate | AI1: Driver_Age_Group | AJ1: Speed_Band
A2: A00001 | B2: =1 -> 1 | C2: Jammu and Kashmir | D2: =VLOOKUP(Table1[[#This Row],[State Name]], Lookup!$A$2:$B$33, 2, FALSE) -> JK | E2: Unknown | F2: 2021 | G2: May | H2: =MONTH(DATEVALUE(G2 & " 5")) -> 5 | I2: =DATE(Table1[[#This Row],[Year]],Table1[[#This Row],[Month_Number]],1) -> 44317 | J2: Monday | K2: 1:46 | L2: Serious | M2: 5 | N2: Cycle | O2: 0 | P2: 4 | Q2: Hazy | R2: National Highway | S2: Wet | T2: Dark | U2: Signs | V2: 61 | W2: 66 | X2: =IF(Table1[[#This Row],[Driver Age]]<25,"(<25) Young",IF(Table1[[#This Row],[Driver Age]]<=60,"(25–60) Adult","(>60) Senior")) -> (>60) Senior | Y2: Male | Z2: Unknown | AA2: Yes | AB2: Curve | AC2: 1 | AD2: Night | AE2: 2020–2021 | AF2: Weekday | AG2: Fatal | AH2: 0 | AI2: 65+ | AJ2: 50–69
A3: A00002 | B3: =1 -> 1 | C3: Uttar Pradesh | D3: =VLOOKUP(Table1[[#This Row],[State Name]], Lookup!$A$2:$B$33, 2, FALSE) -> UP | E3: Lucknow | F3: 2018 | G3: January | H3: =MONTH(DATEVALUE(G3 & " 5")) -> 1 | I3: =DATE(Table1[[#This Row],[Year]],Table1[[#This Row],[Month_Number]],1) -> 43101 | J3: Wednesday | K3: 21:30 | L3: Minor | M3: 5 | N3: Truck | O3: 5 | P3: 4 | Q3: Hazy | R3: Urban Road | S3: Dry | T3: Dusk | U3: Signs | V3: 92 | W3: 60 | X3: =IF(Table1[[#This Row],[Driver Age]]<25,"(<25) Young",IF(Table1[[#This Row],[Driver Age]]<=60,"(25–60) Adult","(>60) Senior")) -> (25–60) Adult | Y3: Male | Z3: Unknown | AA3: Yes | AB3: Straight Road | AC3: 21 | AD3: Night | AE3: 2018–2019 | AF3: Weekday | AG3: Fatal | AH3: 0.8 | AI3: 50-64 | AJ3: 90–109
A4: A00003 | B4: =1 -> 1 | C4: Chhattisgarh | D4: =VLOOKUP(Table1[[#This Row],[State Name]], Lookup!$A$2:$B$33, 2, FALSE) -> CG | E4: Unknown | F4: 2023 | G4: May | H4: =MONTH(DATEVALUE(G4 & " 5")) -> 5 | I4: =DATE(Table1[[#This Row],[Year]],Table1[[#This Row],[Month_Number]],1) -> 45047 | J4: Wednesday | K4: 5:37 | L4: Minor | M4: 5 | N4: Pedestrian | O4: 6 | P4: 5 | Q4: Foggy | R4: National Highway | S4: Under Construction | T4: Dawn | U4: Signs | V4: 120 | W4: 26 | X4: =IF(Table1[[#This Row],[Driver Age]]<25,"(<25) Young",IF(Table1[[#This Row],[Driver Age]]<=60,"(25–60) Adult","(>60) Senior")) -> (25–60) Adult | Y4: Female | Z4: Unknown | AA4: No | AB4: Bridge | AC4: 5 | AD4: Morning | AE4: 2022–2023 | AF4: Weekday | AG4: Fatal | AH4: 0.83 | AI4: 25-34 | AJ4: 110+
A5: A00004 | B5: =1 -> 1 | C5: Uttar Pradesh | D5: =VLOOKUP(Table1[[#This Row],[State Name]], Lookup!$A$2:$B$33, 2, FALSE) -> UP | E5: Lucknow | F5: 2020 | G5: June | H5: =MONTH(DATEVALUE(G5 & " 5")) -> 6 | I5: =DATE(Table1[[#This Row],[Year]],Table1[[#This Row],[Month_Number]],1) -> 43983 | J5: Saturday | K5: 0:31 | L5: Minor | M5: 3 | N5: Bus | O5: 10 | P5: 5 | Q5: Rainy | R5: State Highway | S5: Dry | T5: Dark | U5: Signals | V5: 76 | W5: 34 | X5: =IF(Table1[[#This Row],[Driver Age]]<25,"(<25) Young",IF(Table1[[#This Row],[Driver Age]]<=60,"(25–60) Adult","(>60) Senior")) -> (25–60) Adult | Y5: Female | Z5: Valid | AA5: Yes | AB5: Straight Road | AC5: 0 | AD5: Night | AE5: 2020–2021 | AF5: Weekend | AG5: Fatal | AH5: 0.5 | AI5: 25-34 | AJ5: 70–89
A6: A00005 | B6: =1 -> 1 | C6: Sikkim | D6: =VLOOKUP(Table1[[#This Row],[State Name]], Lookup!$A$2:$B$33, 2, FALSE) -> SK | E6: Unknown | F6: 2021 | G6: August | H6: =MONTH(DATEVALUE(G6 & " 5")) -> 8 | I6: =DATE(Table1[[#This Row],[Year]],Table1[[#This Row],[Month_Number]],1) -> 44409 | J6: Thursday | K6: 11:21 | L6: Minor | M6: 5 | N6: Cycle | O6: 7 | P6: 1 | Q6: Foggy | R6: Urban Road | S6: Wet | T6: Dusk | U6: Signs | V6: 115 | W6: 30 | X6: =IF(Table1[[#This Row],[Driver Age]]<25,"(<25) Young",IF(Table1[[#This Row],[Driver Age]]<=60,"(25–60) Adult","(>60) Senior")) -> (25–60) Adult | Y6: Male | Z6: Unknown | AA6: No | AB6: Intersection | AC6: 11 | AD6: Morning | AE6: 2020–2021 | AF6: Weekday | AG6: Fatal | AH6: 0.14 | AI6: 25-34 | AJ6: 110+
A7: A00006 | B7: =1 -> 1 | C7: Meghalaya | D7: =VLOOKUP(Table1[[#This Row],[State Name]], Lookup!$A$2:$B$33, 2, FALSE) -> ML | E7: Unknown | F7: 2020 | G7: November | H7: =MONTH(DATEVALUE(G7 & " 5")) -> 11 | I7: =DATE(Table1[[#This Row],[Year]],Table1[[#This Row],[Month_Number]],1) -> 44136 | J7: Tuesday | K7: 8:4 | L7: Serious | M7: 1 | N7: Truck | O7: 6 | P7: 2 | Q7: Stormy | R7: Village Road | S7: Dry | T7: Daylight | U7: Police Checkpost | V7: 48 | W7: 44 | X7: =IF(Table1[[#This Row],[Driver Age]]<25,"(<25) Young",IF(Table1[[#This Row],[Driver Age]]<=60,"(25–60) Adult","(>60) Senior")) -> (25–60) Adult | Y7: Male | Z7: Expired | AA7: Yes | AB7: Bridge | AC7: 8 | AD7: Morning | AE7: 2020–2021 | AF7: Weekday | AG7: Fatal | AH7: 0.33 | AI7: 35-49 | AJ7: 30–49
A8: A00007 | B8: =1 -> 1 | C8: Sikkim | D8: =VLOOKUP(Table1[[#This Row],[State Name]], Lookup!$A$2:$B$33, 2, FALSE) -> SK | E8: Unknown | F8: 2021 | G8: October | H8: =MONTH(DATEVALUE(G8 & " 5")) -> 10 | I8: =DATE(Table1[[#This Row],[Year]],Table1[[#This Row],[Month_Number]],1) -> 44470 | J8: Monday | K8: 18:55 | L8: Fatal | M8: 2 | N8: Two-Wheeler | O8: 9 | P8: 5 | Q8: Foggy | R8: Urban Road | S8: Under Construction | T8: Dusk | U8: Police Checkpost | V8: 111 | W8: 48 | X8: =IF(Table1[[#This Row],[Driver Age]]<25,"(<25) Young",IF(Table1[[#This Row],[Driver Age]]<=60,"(25–60) Adult","(>60) Senior")) -> (25–60) Adult | Y8: Female | Z8: Unknown | AA8: No | AB8: Straight Road | AC8: 18 | AD8: Evening | AE8: 2020–2021 | AF8: Weekday | AG8: Fatal | AH8: 0.56 | AI8: 35-49 | AJ8: 110+
A9: A00008 | B9: =1 -> 1 | C9: Himachal Pradesh | D9: =VLOOKUP(Table1[[#This Row],[State Name]], Lookup!$A$2:$B$33, 2, FALSE) -> HP | E9: Unknown | F9: 2022 | G9: December | H9: =MONTH(DATEVALUE(G9 & " 5")) -> 12 | I9: =DATE(Table1[[#This Row],[Year]],Table1[[#This Row],[Month_Number]],1) -> 44896 | J9: Wednesday | K9: 11:40 | L9: Minor | M9: 3 | N9: Truck | O9: 1 | P9: 5 | Q9: Clear | R9: State Highway | S9: Damaged | T9: Dark | U9: Police Checkpost | V9: 62 | W9: 42 | X9: =IF(Table1[[#This Row],[Driver Age]]<25,"(<25) Young",IF(Table1[[#This Row],[Driver Age]]<=60,"(25–60) Adult","(>60) Senior")) -> (25–60) Adult | Y9: Female | Z9: Valid | AA9: No | AB9: Curve | AC9: 11 | AD9: Morning | AE9: 2022–2023 | AF9: Weekday | AG9: Fatal | AH9: 5 | AI9: 35-49 | AJ9: 50–69
A10: A00009 | B10: =1 -> 1 | C10: Rajasthan | D10: =VLOOKUP(Table1[[#This Row],[State Name]], Lookup!$A$2:$B$33, 2, FALSE) -> RJ | E10: Jodhpur | F10: 2021 | G10: July | H10: =MONTH(DATEVALUE(G10 & " 5")) -> 7 | I10: =DATE(Table1[[#This Row],[Year]],Table1[[#This Row],[Month_Number]],1) -> 44378 | J10: Saturday | K10: 8:26 | L10: Fatal | M10: 3 | N10: Truck | O10: 7 | P10: 1 | Q10: Clear | R10: Urban Road | S10: Damaged | T10: Dawn | U10: Signs | V10: 35 | W10: 53 | X10: =IF(Table1[[#This Row],[Driver Age]]<25,"(<25) Young",IF(Table1[[#This Row],[Driver Age]]<=60,"(25–60) Adult","(>60) Senior")) -> (25–60) Adult | Y10: Male | Z10: Valid | AA10: No | AB10: Straight Road | AC10: 8 | AD10: Morning | AE10: 2020–2021 | AF10: Weekend | AG10: Fatal | AH10: 0.14 | AI10: 50-64 | AJ10: 30–49
A11: A00010 | B11: =1 -> 1 | C11: Rajasthan | D11: =VLOOKUP(Table1[[#This Row],[State Name]], Lookup!$A$2:$B$33, 2, FALSE) -> RJ | E11: Jodhpur | F11: 2018 | G11: August | H11: =MONTH(DATEVALUE(G11 & " 5")) -> 8 | I11: =DATE(Table1[[#This Row],[Year]],Table1[[#This Row],[Month_Number]],1) -> 43313 | J11: Saturday | K11: 2:1 | L11: Fatal | M11: 2 | N11: Car | O11: 3 | P11: 2 | Q11: Foggy | R11: State Highway | S11: Under Construction | T11: Dark | U11: Signs | V11: 110 | W11: 50 | X11: =IF(Table1[[#This Row],[Driver Age]]<25,"(<25) Young",IF(Table1[[#This Row],[Driver Age]]<=60,"(25–60) Adult","(>60) Senior")) -> (25–60) Adult | Y11: Female | Z11: Unknown | AA11: Yes | AB11: Straight Road | AC11: 2 | AD11: Night | AE11: 2018–2019 | AF11: Weekend | AG11: Fatal | AH11: 0.67 | AI11: 50-64 | AJ11: 110+
A12: A00011 | B12: =1 -> 1 | C12: Himachal Pradesh | D12: =VLOOKUP(Table1[[#This Row],[State Name]], Lookup!$A$2:$B$33, 2, FALSE) -> HP | E12: Unknown | F12: 2020 | G12: April | H12: =MONTH(DATEVALUE(G12 & " 5")) -> 4 | I12: =DATE(Table1[[#This Row],[Year]],Table1[[#This Row],[Month_Number]],1) -> 43922 | J12: Thursday | K12: 22:25 | L12: Minor | M12: 5 | N12: Pedestrian | O12: 1 | P12: 3 | Q12: Hazy | R12: National Highway | S12: Dry | T12: Dusk | U12: Signals | V12: 35 | W12: 49 | X12: =IF(Table1[[#This Row],[Driver Age]]<25,"(<25) Young",IF(Table1[[#This Row],[Driver Age]]<=60,"(25–60) Adult","(>60) Senior")) -> (25–60) Adult | Y12: Female | Z12: Unknown | AA12: No | AB12: Straight Road | AC12: 22 | AD12: Night | AE12: 2020–2021 | AF12: Weekday | AG12: Fatal | AH12: 3 | AI12: 35-49 | AJ12: 30–49
A13: A00012 | B13: =1 -> 1 | C13: Uttar Pradesh | D13: =VLOOKUP(Table1[[#This Row],[State Name]], Lookup!$A$2:$B$33, 2, FALSE) -> UP | E13: Kanpur | F13: 2018 | G13: August | H13: =MONTH(DATEVALUE(G13 & " 5")) -> 8 | I13: =DATE(Table1[[#This Row],[Year]],Table1[[#This Row],[Month_Number]],1) -> 43313 | J13: Tuesday | K13: 16:49 | L13: Fatal | M13: 3 | N13: Bus | O13: 1 | P13: 4 | Q13: Clear | R13: National Highway | S13: Wet | T13: Dusk | U13: Unknown | V13: 46 | W13: 41 | X13: =IF(Table1[[#This Row],[Driver Age]]<25,"(<25) Young",IF(Table1[[#This Row],[Driver Age]]<=60,"(25–60) Adult","(>60) Senior")) -> (25–60) Adult | Y13: Male | Z13: Valid | AA13: No | AB13: Curve | AC13: 16 | AD13: Afternoon | AE13: 2018–2019 | AF13: Weekday | AG13: Fatal | AH13: 4 | AI13: 35-49 | AJ13: 30–49
... A3001: A03000 | B3001: =1 -> 1 | C3001: Arunachal Pradesh | D3001: =VLOOKUP(Table1[[#This Row],[State Name]], Lookup!$A$2:$B$33, 2, FALSE) -> AR | E3001: Unknown | F3001: 2020 | G3001: September | H3001: =MONTH(DATEVALUE(G3001 & " 5")) -> 9 | I3001: =DATE(Table1[[#This Row],[Year]],Table1[[#This Row],[Month_Number]],1) -> 44075 | J3001: Monday | K3001: 7:19 | L3001: Fatal | M3001: 5 | N3001: Cycle | O3001: 1 | P3001: 3 | Q3001: Hazy | R3001: National Highway | S3001: Under Construction | T3001: Daylight | U3001: Unknown | V3001: 40 | W3001: 66 | X3001: =IF(Table1[[#This Row],[Driver Age]]<25,"(<25) Young",IF(Table1[[#This Row],[Driver Age]]<=60,"(25–60) Adult","(>60) Senior")) -> (>60) Senior | Y3001: Male | Z3001: Unknown | AA3001: Yes | AB3001: Bridge | AC3001: 7 | AD3001: Morning | AE3001: 2020–2021 | AF3001: Weekday | AG3001: Fatal | AH3001: 3 | AI3001: 65+ | AJ3001: 30–49

Sheet KPI
A3: Total Accidents | B3: Total Fatalities | C3: Total Casualties | D3: Avg Fatality Rate per Accident | G3: =IFERROR(GETPIVOTDATA("Total Accidents",$A$3), 0) -> 3000
A4: 3000 | B4: 7366 | C4: 15198 | D4: =IFERROR( IF(GETPIVOTDATA("Total Accidents",$A$3)=0, 0, GETPIVOTDATA("Total Fatalities",$A$3)/GETPIVOTDATA("Total Accidents",$A$3) ), 0) -> 2.4553333 | G4: =IFERROR(GETPIVOTDATA("Total Fatalities",$A$3), 0) -> 7366
G5: =IFERROR(GETPIVOTDATA("Total Casualties",$A$3), 0) -> 15198
A6: Total Accidents | B6: Sum of Number of Vehicles Involved | C6: Avg Vehicles per Accident
A7: 3000 | B7: 8988 | C7: =IFERROR( IF(GETPIVOTDATA("Total Accidents",$A$6)=0, 0, GETPIVOTDATA("Sum of Number of Vehicles Involved",$A$6)/GETPIVOTDATA("Total Accidents",$A$6) ), 0) -> 2.996
A9: Row Labels | B9: Total Accidents | C9: Peak Year | D9: Row Labels | E9: Total Accidents | F9: Peak Month
A10: 2018 | B10: 479 | C10: =IFERROR( INDEX(A10:A15, MATCH(MAX(B10:B15), B10:B15, 0)), 0 ) -> 2020 | D10: January | E10: 256 | F10: {=IFERROR( INDEX(D10:D21, MATCH( MAX( IF((D10:D21<>"Grand Total"), E10:E21) ), E10:E21, 0 ) ), 0)} -> March
A11: 2019 | B11: 468 | D11: February | E11: 240
A12: 2020 | B12: 526 | D12: March | E12: 266
A13: 2021 | B13: 522 | D13: April | E13: 236
A14: 2022 | B14: 521 | D14: May | E14: 246
A15: 2023 | B15: 484 | D15: June | E15: 262
A16: Grand Total | B16: 3000 | D16: July | E16: 236
D17: August | E17: 247
D18: September | E18: 240
D19: October | E19: 261
D20: November | E20: 250
D21: December | E21: 260
D22: Grand Total | E22: 3000
A25: Row Labels | B25: Total Accidents | C25: Top Phase | D25: =IFERROR( INDEX(A26:A28, MATCH(MAX(B26:B28), B26:B28, 0)), 0 ) -> 2020–2021
A26: 2018–2019 | B26: 947 | C26: Accidents | D26: =IFERROR(MAX(B26:B28), 0) -> 1048
A27: 2020–2021 | B27: 1048 | C27: Shares | D27: =IFERROR( IF(SUM(B26:B28)=0, 0, MAX(B26:B28)/SUM(B26:B28)*100), 0) -> 34.933333
A28: 2022–2023 | B28: 1005
A29: Grand Total | B29: 3000
A32: Row Labels | B32: Total Accidents
A33: 2018 | B33: 479
A34: 2019 | B34: 468
A35: 2020 | B35: 526
A36: 2021 | B36: 522
A37: 2022 | B37: 521
A38: 2023 | B38: 484
A39: Grand Total | B39: 3000
A45: Row Labels | B45: Total Accidents | C45: Avg Accidents Per Year | D45: =IFERROR( IF(COUNTA(_xlfn.UNIQUE(A46:A51))=0, 0, GETPIVOTDATA("Accident_ID",$A$45)/COUNTA(_xlfn.UNIQUE(A46:A51)) ), 0) -> 500
A46: 2018 | B46: 479
A47: 2019 | B47: 468
A48: 2020 | B48: 526
A49: 2021 | B49: 522
A50: 2022 | B50: 521
A51: 2023 | B51: 484
A52: Grand Total | B52: 3000
...

Sheet Charts
A3: Row Labels | B3: Accidents
A4: 2018 | B4: 479
A5: 2019 | B5: 468
A6: 2020 | B6: 526
A7: 2021 | B7: 522
A8: 2022 | B8: 521
A9: 2023 | B9: 484
A10: Grand Total | B10: 3000
A19: Row Labels | B19: Casualties | C19: Fatalities
A20: Fatal | B20: 4999 | C20: 2384
A21: Minor | B21: 5182 | C21: 2531
A22: Serious | B22: 5017 | C22: 2451
A23: Grand Total | B23: 15198 | C23: 7366
A30: Row Labels | B30: Accidents
A31: Fatal | B31: 985
A32: Minor | B32: 1034
A33: Serious | B33: 981
A34: Grand Total | B34: 3000
A38: Row Labels | B38: Count of Accident_ID
A39: Afternoon | B39: 597
A40: Evening | B40: 470
A41: Morning | B41: 894
A42: Night | B42: 1039
A43: Grand Total | B43: 3000
A46: Row Labels | B46: Count of Accident_ID
A47: 2018–2019 | B47: 947
A48: 2020–2021 | B48: 1048
A49: 2022–2023 | B49: 1005
A50: Grand Total | B50: 3000
A53: Row Labels | B53: Accidents
A54: January | B54: 256
A55: February | B55: 240
A56: March | B56: 266
A57: April | B57: 236
A58: May | B58: 246
A59: June | B59: 262
A60: July | B60: 236
A61: August | B61: 247
A62: September | B62: 240
A63: October | B63: 261
...

Sheet Slicers
A3: Row Labels
A4: 2018
A5: 2019
A6: 2020
A7: 2021
A8: 2022
A9: 2023
A10: Grand Total
E21: cs
A24: Row Labels
A25: Andhra Pradesh
A26: Arunachal Pradesh
A27: Assam
A28: Bihar
A29: Chandigarh
A30: Chhattisgarh
A31: Delhi
A32: Goa
A33: Gujarat
A34: Haryana
A35: Himachal Pradesh
... A92: West Bengal

Sheet KPI Summary

Sheet Overview

Sheet Temporal

Sheet Severity

Sheet Geography

Sheet Driver

Sheet Environment

Sheet Vehicles

Sheet Road Conditions
